Analyzing the provided code, I've identified a potential security weakness:

Line 70-76: Following the CWE-388 (Error Handling) standard, a silent return of an elevated error occurs here. After failed retrieval of the expected resource, instead of raising an exception, a dictionary with a null UUID key value is returned. This might cover the possible error and lead to undefined behavior later if the function '_get_rp_by_name()' fails.

Solution: The code should appropriately handle errors, and raise exceptions when needed. Rather than returning a dictionary with a null UUID key value, consider throwing an exception or an error at this point. Then, handle this exception at the points of invocation to ensure that the program's execution does not continue in an erroneous state. The error message should also provide enough detail for the user to understand what went wrong, and steps they should take (if any). 

Here's an example of how you could adjust the code:

```python
if len(rps) != 1:
    # Raise an exception with a detailed message
    raise ValueError(f"Invalid count of resource providers for name: {name} . Expected: 1, Got: {len(rps)}")
return rps[0]
```

This makes the code more robust and secure as it will prevent the silent propagation of an error throughout the system.