After reviewing the provided OpenStack Nova code, I found a potential security concern related to error handling and exception masking, which could obscure the underlying issues during the runtime:

### Security Defect:
**Issue:** Exception masking in the decorated function `set_update_time_on_success` (lines 79-100).
- **Description:** The `except` block at lines 87-93 captures and logs all exceptions without re-raising them. This behavior can potentially mask underlying errors that occur in the `function` being decorated. This might make the system ignore critical errors during host state updates, affecting the scheduler's decision-making process.
- **Consequences:** By not re-raising exceptions after logging, the system could continue to operate under erroneous states without halting or alerting adequately, which may lead to resource allocation issues or failures in instance creation that are not properly reported back to the user or system administrator.

### Recommended Solution:
- **Action:** Modify the exception handling in `set_update_time_on_success` to ensure that after logging the warning, the exception is re-raised to be handled or logged by the caller, or handled by a broader exception management strategy in the system.
- **Code Change:**
  ```python
  except Exception as e:
      LOG.warning(_LW("Selected host: %(host)s failed to consume from "
                      "instance. Error: %(error)s"),
                  {'host': self.host, 'error': e})
      raise  # Re-raise the exception to ensure it's not silently ignored.
  ```
This change ensures that the exception is not silently swallowed, thus maintaining the integrity of the system's error handling and alerting mechanisms.

Overall, the rest of the code handles resources and concurrency with appropriate locking mechanisms and error handling, consistent with good practices in managing complex systems like OpenStack Nova. However, it's crucial to address the exception masking issue to avoid potential operational and security risks.